<?xml version="1.0"?>
<robot name="astar_robot">

  <link name="base_link">
    <visual>
      <geometry><box size="0.4 0.3 0.1"/></geometry>
      <material name="blue"><color rgba="0.2 0.2 0.8 1.0"/></material>
    </visual>
    <collision>
      <geometry><box size="0.4 0.3 0.1"/></geometry>
    </collision>
    <inertial>
      <mass value="1.0"/>
      <inertia ixx="0.01" ixy="0" ixz="0" iyy="0.01" iyz="0" izz="0.01"/>
    </inertial>
  </link>

  <link name="left_wheel">
    <visual>
      <geometry><cylinder radius="0.08" length="0.04"/></geometry>
      <material name="black"><color rgba="0.1 0.1 0.1 1"/></material>
    </visual>
    <collision><geometry><cylinder radius="0.08" length="0.04"/></geometry></collision>
    <inertial>
      <mass value="0.2"/>
      <inertia ixx="0.001" ixy="0" ixz="0" iyy="0.001" iyz="0" izz="0.001"/>
    </inertial>
  </link>

  <joint name="left_wheel_joint" type="continuous">
    <parent link="base_link"/>
    <child link="left_wheel"/>
    <origin xyz="0.0 0.17 -0.05" rpy="-1.5707 0 0"/>
    <axis xyz="0 0 1"/>
  </joint>

  <link name="right_wheel">
    <visual>
      <geometry><cylinder radius="0.08" length="0.04"/></geometry>
      <material name="black"><color rgba="0.1 0.1 0.1 1"/></material>
    </visual>
    <collision><geometry><cylinder radius="0.08" length="0.04"/></geometry></collision>
    <inertial>
      <mass value="0.2"/>
      <inertia ixx="0.001" ixy="0" ixz="0" iyy="0.001" iyz="0" izz="0.001"/>
    </inertial>
  </link>

  <joint name="right_wheel_joint" type="continuous">
    <parent link="base_link"/>
    <child link="right_wheel"/>
    <origin xyz="0.0 -0.17 -0.05" rpy="-1.5707 0 0"/>
    <axis xyz="0 0 1"/>
  </joint>

</robot>
